[2024-04-26T13:22:47.813+0000] {taskinstance.py:1103} INFO - Dependencies all met for dep_context=non-requeueable deps ti=<TaskInstance: 1_init_once_seed_data.load_seed_data_once manual__2024-04-26T13:22:46.819516+00:00 [queued]>
[2024-04-26T13:22:47.821+0000] {taskinstance.py:1103} INFO - Dependencies all met for dep_context=requeueable deps ti=<TaskInstance: 1_init_once_seed_data.load_seed_data_once manual__2024-04-26T13:22:46.819516+00:00 [queued]>
[2024-04-26T13:22:47.821+0000] {taskinstance.py:1308} INFO - Starting attempt 1 of 1
[2024-04-26T13:22:47.832+0000] {taskinstance.py:1327} INFO - Executing <Task(BashOperator): load_seed_data_once> on 2024-04-26 13:22:46.819516+00:00
[2024-04-26T13:22:47.836+0000] {standard_task_runner.py:57} INFO - Started process 1260 to run task
[2024-04-26T13:22:47.839+0000] {standard_task_runner.py:84} INFO - Running: ['***', 'tasks', 'run', '1_init_once_seed_data', 'load_seed_data_once', 'manual__2024-04-26T13:22:46.819516+00:00', '--job-id', '66', '--raw', '--subdir', 'DAGS_FOLDER/init.py', '--cfg-path', '/tmp/tmpt70i5cvp']
[2024-04-26T13:22:47.840+0000] {standard_task_runner.py:85} INFO - Job 66: Subtask load_seed_data_once
[2024-04-26T13:22:47.897+0000] {task_command.py:410} INFO - Running <TaskInstance: 1_init_once_seed_data.load_seed_data_once manual__2024-04-26T13:22:46.819516+00:00 [running]> on host 511926b065ed
[2024-04-26T13:22:47.997+0000] {taskinstance.py:1547} INFO - Exporting env vars: AIRFLOW_CTX_DAG_OWNER='***' AIRFLOW_CTX_DAG_ID='1_init_once_seed_data' AIRFLOW_CTX_TASK_ID='load_seed_data_once' AIRFLOW_CTX_EXECUTION_DATE='2024-04-26T13:22:46.819516+00:00' AIRFLOW_CTX_TRY_NUMBER='1' AIRFLOW_CTX_DAG_RUN_ID='manual__2024-04-26T13:22:46.819516+00:00'
[2024-04-26T13:22:47.999+0000] {subprocess.py:63} INFO - Tmp dir root location: /tmp
[2024-04-26T13:22:48.000+0000] {subprocess.py:75} INFO - Running command: ['/bin/bash', '-c', 'cd /dbt && dbt seed --profiles-dir .']
[2024-04-26T13:22:48.009+0000] {subprocess.py:86} INFO - Output:
[2024-04-26T13:22:49.773+0000] {subprocess.py:93} INFO - [0m13:22:49  Running with dbt=1.5.2
[2024-04-26T13:22:50.332+0000] {subprocess.py:93} INFO - [0m13:22:50  Registered adapter: snowflake=1.5.1
[2024-04-26T13:22:50.363+0000] {subprocess.py:93} INFO - [0m13:22:50  Unable to do partial parsing because saved manifest not found. Starting full parse.
[2024-04-26T13:22:51.543+0000] {subprocess.py:93} INFO - [0m13:22:51  [[33mWARNING[0m]: Configuration paths exist in your dbt_project.yml file which do not apply to any resources.
[2024-04-26T13:22:51.543+0000] {subprocess.py:93} INFO - There are 2 unused configuration paths:
[2024-04-26T13:22:51.544+0000] {subprocess.py:93} INFO - - models.dbt.transform
[2024-04-26T13:22:51.544+0000] {subprocess.py:93} INFO - - models.dbt.analysis
[2024-04-26T13:22:51.564+0000] {subprocess.py:93} INFO - [0m13:22:51  Found 5 models, 1 test, 0 snapshots, 0 analyses, 438 macros, 0 operations, 4 seed files, 0 sources, 0 exposures, 0 metrics, 0 groups
[2024-04-26T13:22:51.567+0000] {subprocess.py:93} INFO - [0m13:22:51
[2024-04-26T13:22:52.274+0000] {subprocess.py:93} INFO - [0m13:22:52
[2024-04-26T13:22:52.275+0000] {subprocess.py:93} INFO - [0m13:22:52  Finished running  in 0 hours 0 minutes and 0.71 seconds (0.71s).
[2024-04-26T13:22:52.276+0000] {subprocess.py:93} INFO - [0m13:22:52  Encountered an error:
[2024-04-26T13:22:52.277+0000] {subprocess.py:93} INFO - Runtime Error
[2024-04-26T13:22:52.277+0000] {subprocess.py:93} INFO -   Database error while listing schemas in database "demo_dbt"
[2024-04-26T13:22:52.278+0000] {subprocess.py:93} INFO -   Database Error
[2024-04-26T13:22:52.278+0000] {subprocess.py:93} INFO -     250001 (08001): Failed to connect to DB: ay58901.eu-central-1.snowflakecomputing.com:443. Your free trial has ended and all of your virtual warehouses have been suspended. Add billing information in the Snowflake web UI to continue using the full set of Snowflake features.
[2024-04-26T13:22:53.041+0000] {subprocess.py:97} INFO - Command exited with return code 2
[2024-04-26T13:22:53.054+0000] {taskinstance.py:1824} ERROR - Task failed with exception
Traceback (most recent call last):
  File "/home/airflow/.local/lib/python3.7/site-packages/airflow/operators/bash.py", line 211, in execute
    f"Bash command failed. The command returned a non-zero exit code {result.exit_code}."
airflow.exceptions.AirflowException: Bash command failed. The command returned a non-zero exit code 2.
[2024-04-26T13:22:53.059+0000] {taskinstance.py:1350} INFO - Marking task as FAILED. dag_id=1_init_once_seed_data, task_id=load_seed_data_once, execution_date=20240426T132246, start_date=20240426T132247, end_date=20240426T132253
[2024-04-26T13:22:53.075+0000] {standard_task_runner.py:109} ERROR - Failed to execute job 66 for task load_seed_data_once (Bash command failed. The command returned a non-zero exit code 2.; 1260)
[2024-04-26T13:22:53.089+0000] {local_task_job_runner.py:225} INFO - Task exited with return code 1
[2024-04-26T13:22:53.104+0000] {taskinstance.py:2653} INFO - 0 downstream tasks scheduled from follow-on schedule check
