[2023-07-09T07:10:24.932+0000] {taskinstance.py:1103} INFO - Dependencies all met for dep_context=non-requeueable deps ti=<TaskInstance: 1_init_once_seed_data.load_seed_data_once manual__2023-07-09T07:03:55.361926+00:00 [queued]>
[2023-07-09T07:10:24.938+0000] {taskinstance.py:1103} INFO - Dependencies all met for dep_context=requeueable deps ti=<TaskInstance: 1_init_once_seed_data.load_seed_data_once manual__2023-07-09T07:03:55.361926+00:00 [queued]>
[2023-07-09T07:10:24.938+0000] {taskinstance.py:1308} INFO - Starting attempt 2 of 2
[2023-07-09T07:10:24.946+0000] {taskinstance.py:1327} INFO - Executing <Task(BashOperator): load_seed_data_once> on 2023-07-09 07:03:55.361926+00:00
[2023-07-09T07:10:24.949+0000] {standard_task_runner.py:57} INFO - Started process 79 to run task
[2023-07-09T07:10:24.952+0000] {standard_task_runner.py:84} INFO - Running: ['***', 'tasks', 'run', '1_init_once_seed_data', 'load_seed_data_once', 'manual__2023-07-09T07:03:55.361926+00:00', '--job-id', '46', '--raw', '--subdir', 'DAGS_FOLDER/init.py', '--cfg-path', '/tmp/tmp2murb2in']
[2023-07-09T07:10:24.953+0000] {standard_task_runner.py:85} INFO - Job 46: Subtask load_seed_data_once
[2023-07-09T07:10:24.990+0000] {task_command.py:410} INFO - Running <TaskInstance: 1_init_once_seed_data.load_seed_data_once manual__2023-07-09T07:03:55.361926+00:00 [running]> on host 8f42e64974a7
[2023-07-09T07:10:25.067+0000] {taskinstance.py:1547} INFO - Exporting env vars: AIRFLOW_CTX_DAG_OWNER='***' AIRFLOW_CTX_DAG_ID='1_init_once_seed_data' AIRFLOW_CTX_TASK_ID='load_seed_data_once' AIRFLOW_CTX_EXECUTION_DATE='2023-07-09T07:03:55.361926+00:00' AIRFLOW_CTX_TRY_NUMBER='2' AIRFLOW_CTX_DAG_RUN_ID='manual__2023-07-09T07:03:55.361926+00:00'
[2023-07-09T07:10:25.069+0000] {subprocess.py:63} INFO - Tmp dir root location: /tmp
[2023-07-09T07:10:25.069+0000] {subprocess.py:75} INFO - Running command: ['/bin/bash', '-c', 'cd /dbt && dbt seed --profiles-dir .']
[2023-07-09T07:10:25.077+0000] {subprocess.py:86} INFO - Output:
[2023-07-09T07:10:26.469+0000] {subprocess.py:93} INFO - [0m07:10:26  Running with dbt=1.5.2
[2023-07-09T07:10:27.343+0000] {subprocess.py:93} INFO - [0m07:10:27  Registered adapter: snowflake=1.5.1
[2023-07-09T07:10:27.508+0000] {subprocess.py:93} INFO - [0m07:10:27  [[33mWARNING[0m]: Configuration paths exist in your dbt_project.yml file which do not apply to any resources.
[2023-07-09T07:10:27.508+0000] {subprocess.py:93} INFO - There are 2 unused configuration paths:
[2023-07-09T07:10:27.509+0000] {subprocess.py:93} INFO - - models.dbt.analysis
[2023-07-09T07:10:27.509+0000] {subprocess.py:93} INFO - - models.dbt.transform
[2023-07-09T07:10:27.523+0000] {subprocess.py:93} INFO - [0m07:10:27  Found 5 models, 1 test, 0 snapshots, 0 analyses, 438 macros, 0 operations, 4 seed files, 0 sources, 0 exposures, 0 metrics, 0 groups
[2023-07-09T07:10:27.526+0000] {subprocess.py:93} INFO - [0m07:10:27
[2023-07-09T07:10:29.054+0000] {subprocess.py:93} INFO - [0m07:10:29  Concurrency: 200 threads (target='dev')
[2023-07-09T07:10:29.056+0000] {subprocess.py:93} INFO - [0m07:10:29
[2023-07-09T07:10:29.084+0000] {subprocess.py:93} INFO - [0m07:10:29  1 of 4 START seed file public.bookings_1 ....................................... [RUN]
[2023-07-09T07:10:29.086+0000] {subprocess.py:93} INFO - [0m07:10:29  2 of 4 START seed file public.bookings_2 ....................................... [RUN]
[2023-07-09T07:10:29.087+0000] {subprocess.py:93} INFO - [0m07:10:29  3 of 4 START seed file public.customers ........................................ [RUN]
[2023-07-09T07:10:29.088+0000] {subprocess.py:93} INFO - [0m07:10:29  4 of 4 START seed file public.library_transaction .............................. [RUN]
[2023-07-09T07:10:29.720+0000] {subprocess.py:93} INFO - [0m07:10:29  4 of 4 ERROR loading seed file public.library_transaction ...................... [[31mERROR[0m in 0.63s]
[2023-07-09T07:10:32.128+0000] {subprocess.py:93} INFO - [0m07:10:32  2 of 4 OK loaded seed file public.bookings_2 ................................... [[32mINSERT 7[0m in 3.03s]
[2023-07-09T07:10:32.130+0000] {subprocess.py:93} INFO - [0m07:10:32  1 of 4 OK loaded seed file public.bookings_1 ................................... [[32mINSERT 7[0m in 3.04s]
[2023-07-09T07:10:32.157+0000] {subprocess.py:93} INFO - [0m07:10:32  3 of 4 OK loaded seed file public.customers .................................... [[32mINSERT 2[0m in 3.06s]
[2023-07-09T07:10:32.279+0000] {subprocess.py:93} INFO - [0m07:10:32
[2023-07-09T07:10:32.281+0000] {subprocess.py:93} INFO - [0m07:10:32  Finished running 4 seeds in 0 hours 0 minutes and 4.75 seconds (4.75s).
[2023-07-09T07:10:32.298+0000] {subprocess.py:93} INFO - [0m07:10:32
[2023-07-09T07:10:32.300+0000] {subprocess.py:93} INFO - [0m07:10:32  [31mCompleted with 1 error and 0 warnings:[0m
[2023-07-09T07:10:32.301+0000] {subprocess.py:93} INFO - [0m07:10:32
[2023-07-09T07:10:32.302+0000] {subprocess.py:93} INFO - [0m07:10:32  [33mCompilation Error in seed library_transaction (seeds/library_transaction.csv)[0m
[2023-07-09T07:10:32.303+0000] {subprocess.py:93} INFO - [0m07:10:32    Row 0 has 3 values, but Table only has 1 columns.
[2023-07-09T07:10:32.304+0000] {subprocess.py:93} INFO - [0m07:10:32
[2023-07-09T07:10:32.305+0000] {subprocess.py:93} INFO - [0m07:10:32    > in macro materialization_seed_default (macros/materializations/seeds/seed.sql)
[2023-07-09T07:10:32.306+0000] {subprocess.py:93} INFO - [0m07:10:32    > called by macro materialization_seed_snowflake (macros/materializations/seed.sql)
[2023-07-09T07:10:32.307+0000] {subprocess.py:93} INFO - [0m07:10:32    > called by seed library_transaction (seeds/library_transaction.csv)
[2023-07-09T07:10:32.308+0000] {subprocess.py:93} INFO - [0m07:10:32
[2023-07-09T07:10:32.309+0000] {subprocess.py:93} INFO - [0m07:10:32  Done. PASS=3 WARN=0 ERROR=1 SKIP=0 TOTAL=4
[2023-07-09T07:10:33.022+0000] {subprocess.py:97} INFO - Command exited with return code 1
[2023-07-09T07:10:33.033+0000] {taskinstance.py:1824} ERROR - Task failed with exception
Traceback (most recent call last):
  File "/home/airflow/.local/lib/python3.7/site-packages/airflow/operators/bash.py", line 211, in execute
    f"Bash command failed. The command returned a non-zero exit code {result.exit_code}."
airflow.exceptions.AirflowException: Bash command failed. The command returned a non-zero exit code 1.
[2023-07-09T07:10:33.036+0000] {taskinstance.py:1350} INFO - Marking task as FAILED. dag_id=1_init_once_seed_data, task_id=load_seed_data_once, execution_date=20230709T070355, start_date=20230709T071024, end_date=20230709T071033
[2023-07-09T07:10:33.050+0000] {standard_task_runner.py:109} ERROR - Failed to execute job 46 for task load_seed_data_once (Bash command failed. The command returned a non-zero exit code 1.; 79)
[2023-07-09T07:10:33.067+0000] {local_task_job_runner.py:225} INFO - Task exited with return code 1
[2023-07-09T07:10:33.080+0000] {taskinstance.py:2653} INFO - 0 downstream tasks scheduled from follow-on schedule check
